Workbook

Sheet v5
A1: ROUNDING | B1: -1 | E1: ROUND | F1: -1
A2: Target Leadership | B2: 531062
A3: Ratio to Calculate G9 F | B3: 0.00182 | C3: Experimental
A4: G9 F Simulation | B4: =+B2*B3 -> 966.53284 | C4: Experimental
B5: TROOPS | C5: LEADERSHIP
A6: DON’T TOUCH | B6: =B4 -> 966.53284
D8: RATIO
A9: G9 Flying | B9: =ROUNDDOWN(B4,-1) -> 960 | C9: =+B6*20 -> 19330.657
A10: S9 Flying | B10: =+ROUNDDOWN($B$6*D10,$B$1) -> 960 | C10: =+B10*20 -> 19200 | D10: 1 | E10: 720
A11: G8 Flying | B11: =+ROUND($B$6*D11,$B$1) -> 1880 | C11: =+B11*20 -> 37600 | D11: 1.944 | E11: 1400
A12: S8 Flying | B12: =+ROUND($B$6*D12,$B$1) -> 1870 | C12: =+B12*20 -> 37400 | D12: 1.93 | E12: 1390
A13: G7 Flying | B13: =+ROUND($B$6*D13,$B$1) -> 3440 | C13: =+B13*20 -> 68800 | D13: 3.555 | E13: 2560
A14: G9 Mounted | B14: =+ROUNDDOWN($B$6*D14,$B$1) -> 9670 | C14: =+B14*2 -> 19340 | D14: 10.014 | E14: 7210
A15: S9 Mounted | B15: =+ROUNDDOWN($B$6*D15,$B$1) -> 9940 | C15: =+B15*2 -> 19880 | D15: 10.291 | E15: 7410
A16: G8 Mounted | B16: =+ROUND($B$6*D16,$B$1) -> 19060 | C16: =+B16*2 -> 38120 | D16: 19.722 | E16: 14200
A17: S8 Mounted | B17: =+ROUND($B$6*D17,$B$1) -> 19440 | C17: =+B17*2 -> 38880 | D17: 20.111 | E17: 14480
A18: G9 Ranged | B18: =+ROUNDDOWN($B$6*D18,$B$1) -> 19140 | C18: =+B18 -> 19140 | D18: 19.805 | E18: 14260
A19: G9 Mounted | B19: =+ROUNDDOWN($B$6*D19,$B$1) -> 19430 | C19: =+B19 -> 19430 | D19: 20.111 | E19: 14480
A20: S9 Ranged | B20: =+ROUNDDOWN($B$6*D20,$B$1) -> 19540 | C20: =+B20 -> 19540 | D20: =+D18*1.0211 -> 20.222885 | E20: 14560
A21: G9 Ranged | B21: =+ROUNDDOWN($B$6*D21,$B$1) -> 20000 | C21: =+B21 -> 20000 | D21: =+D19*1.029 -> 20.694219 | E21: 14900
A22: G8 Ranged | B22: =+ROUND($B$6*D22,$B$1) -> 37180 | C22: =+B22 -> 37180 | D22: 38.472 | E22: 27700
A23: G8 Melee | B23: =+ROUND($B$6*D23,$B$1) -> 38260 | C23: =+B23 -> 38260 | D23: 39.584 | E23: 28500 | G23: =B23/B25 -> 0.98278962
A24: S8 Ranged | B24: =+ROUND($B$6*D24,$B$1) -> 38390 | C24: =+B24 -> 38390 | D24: 39.722 | E24: 28600
A25: S8 Melee | B25: =+ROUND($B$6*D25,$B$1) -> 38930 | C25: =+B25 -> 38930 | D25: 40.278 | E25: 29000
A27: Regular Troops | B27: =SUM(B11:B26) -> 296170 | C27: =SUM(C9:C25) -> 529420.66

Sheet Base Data
A1: INPUTS (transfer from Calcs)
A2: Customization Bonus | B2: =+Calcs!B3 -> 0.175
A3: Talents (Troop Type) | B3: =+Calcs!B4 -> 2.5
A4: Talents (G/S) | B4: =+Calcs!B5 -> 1.5
A5: Hall of Fame | B5: =+Calcs!B6 -> 1.2
A6: Army Mod | B6: =+Calcs!B7 -> 3.1
A7: Health of Captain (Army) | B7: =+Calcs!B8 -> 0
A8: Health of Artifact | B8: =+Calcs!B9 -> 0
A9: Health of Equipment | B9: =+Calcs!B10 -> 3
A10: Dragon | B10: =+Calcs!B11 -> 1.6
A11: VIP | B11: =+Calcs!B12 -> 0.09 | V11: =3*75 -> 225
A12: Clan Capital | B12: =+Calcs!B13 -> 1 | V12: =3*100 -> 300
A13: Clan Army Health Bonus | B13: =+Calcs!B14 -> 0.25 | V13: =3*60 -> 180
A14: Personal Bonuses | B14: =+Calcs!B15 -> 0.25 | L14: 1468 | M14: 1557 | N14: =+M14-L14 -> 89 | V14: =3*50 -> 150
A15: Total Bonus | B15: =SUM(B2:B14) -> 14.665 | V15: =3*25 -> 75
A16: Beasts Bonus (Talents) | B16: =+Calcs!B17 -> 1 | K16: 1572.5 | L16: 2244.5 | V16: =SUM(V11:V15) -> 930
A17: Great Marshal | B17: =+Calcs!B18 -> ON | K17: 1572.5 | L17: 2245.5
A18: Captain Bonus for Guardsmen | B18: =+Calcs!B19 -> 0
A19: Captain Bonus for Specialits | B19: =+Calcs!B20 -> 0 | D19: =54-25 -> 29 | M19: =2337-2250 -> 87
A20: Captain Bonus for Flyings | B20: =+Calcs!B21 -> 0
A21: Captain Bonus for Mounted | B21: =+Calcs!B22 -> 0 | L21: 21.815 | M21: 15.965
A22: Captain Bonus for Ranged | B22: =+Calcs!B23 -> 0 | L22: =+L21-L26 -> 6.8 | M22: =+M21-L27 -> 0.95
A23: Captain Bonus for Melee | B23: =+Calcs!B24 -> 0 | L23: =2242.5%-L30 -> 7.41
A25: Guardsmen | B25: Base Health | C25: Leadership per Troop | D25: Base Bonus | E25: Beast Bonus | F25: Guardsmen Bonus | G25: Flyings Bonus | H25: Mounted Bonus | I25: Ranged Bonus | J25: Melee Bonus | K25: Great Marshal | L25: Total Health Bonus | M25: Health per Troop | N25: Level | O25: Use Increased Buffer
A26: G9 Flyings | B26: 330600 | C26: 20 | D26: =+$B$15+10% -> 14.765 | F26: =+$B$18 -> 0 | G26: =+$B$20 -> 0 | K26: =25%*($B$17="ON") -> 0.25 | L26: =SUM(D26:K26) -> 15.015 | M26: =+B26*L26 -> 4963959 | N26: 9 | P26: =+$P$29 -> 1
A27: G9 Mounted | B27: 33060 | C27: 2 | D27: =+$B$15+10% -> 14.765 | F27: =+$B$18 -> 0 | H27: =+$B$21 -> 0 | K27: =25%*($B$17="ON") -> 0.25 | L27: =SUM(D27:K27) -> 15.015 | M27: =+B27*L27 -> 496395.9 | N27: 9 | P27: =+$P$29 -> 1
A28: G9 Ranged | B28: 16530 | C28: 1 | D28: =+$B$15+10% -> 14.765 | F28: =+$B$18 -> 0 | I28: =+$B$22 -> 0 | K28: =25%*($B$17="ON") -> 0.25 | L28: =SUM(D28:K28) -> 15.015 | M28: =+B28*L28 -> 248197.95 | N28: 9 | P28: =+$P$29 -> 1
A29: G9 Melee | B29: 16530 | C29: 1 | D29: =+$B$15+10% -> 14.765 | F29: =+$B$18 -> 0 | J29: =+$B$23 -> 0 | K29: =25%*($B$17="ON") -> 0.25 | L29: =SUM(D29:K29) -> 15.015 | M29: =+B29*L29 -> 248197.95 | N29: 9 | P29: 1
A30: G8 Flyings | B30: 183600 | C30: 20 | D30: =+$B$15+10% -> 14.765 | F30: =+$B$18 -> 0 | G30: =+$B$20 -> 0 | K30: =25%*($B$17="ON") -> 0.25 | L30: =SUM(D30:K30) -> 15.015 | M30: =+B30*L30 -> 2756754 | N30: =+N26-1 -> 8 | P30: =+$P$33 -> 0.5553539
A31: G8 Mounted | B31: 18360 | C31: 2 | D31: =+$B$15+10% -> 14.765 | F31: =+$B$18 -> 0 | H31: =+$B$21 -> 0 | K31: =25%*($B$17="ON") -> 0.25 | L31: =SUM(D31:K31) -> 15.015 | M31: =+B31*L31 -> 275675.4 | N31: =+N27-1 -> 8 | P31: =+$P$33 -> 0.5553539
A32: G8 Ranged | B32: 9180 | C32: 1 | D32: =+$B$15+10% -> 14.765 | F32: =+$B$18 -> 0 | I32: =+$B$22 -> 0 | K32: =25%*($B$17="ON") -> 0.25 | L32: =SUM(D32:K32) -> 15.015 | M32: =+B32*L32 -> 137837.7 | N32: =+N28-1 -> 8 | P32: =+$P$33 -> 0.5553539
A33: G8 Melee | B33: 9180 | C33: 1 | D33: =+$B$15+10% -> 14.765 | F33: =+$B$18 -> 0 | J33: =+$B$23 -> 0 | K33: =25%*($B$17="ON") -> 0.25 | L33: =SUM(D33:K33) -> 15.015 | M33: =+B33*L33 -> 137837.7 | N33: =+N29-1 -> 8 | P33: =+B33/$B$29 -> 0.5553539
A34: G7 Flyings | B34: 102000 | C34: 20 | D34: =+$B$15+10% -> 14.765 | E34: =+$B$16 -> 1 | F34: =+$B$18 -> 0 | G34: =+$B$20 -> 0 | K34: =25%*($B$17="ON") -> 0.25 | L34: =SUM(D34:K34) -> 16.015 | M34: =+B34*L34 -> 1633530 | N34: =+N30-1 -> 7 | P34: =+$P$37 -> 0.30852995
A35: G7 Mounted | B35: 10200 | C35: 2 | D35: =+$B$15+10% -> 14.765 | F35: =+$B$18 -> 0 | H35: =+$B$21 -> 0 | K35: =25%*($B$17="ON") -> 0.25 | L35: =SUM(D35:K35) -> 15.015 | M35: =+B35*L35 -> 153153 | N35: =+N31-1 -> 7 | P35: =+$P$37 -> 0.30852995
A36: G7 Ranged | B36: 5100 | C36: 1 | D36: =+$B$15+10% -> 14.765 | F36: =+$B$18 -> 0 | I36: =+$B$22 -> 0 | K36: =25%*($B$17="ON") -> 0.25 | L36: =SUM(D36:K36) -> 15.015 | M36: =+B36*L36 -> 76576.5 | N36: =+N32-1 -> 7 | P36: =+$P$37 -> 0.30852995
A37: G7 Melee | B37: 5100 | C37: 1 | D37: =+$B$15+10% -> 14.765 | F37: =+$B$18 -> 0 | J37: =+$B$23 -> 0 | K37: =25%*($B$17="ON") -> 0.25 | L37: =SUM(D37:K37) -> 15.015 | M37: =+B37*L37 -> 76576.5 | N37: =+N33-1 -> 7 | P37: =+B37/$B$29 -> 0.30852995
A38: G6 Flyings | B38: 57000 | C38: 20 | D38: =+$B$15+10% -> 14.765 | E38: =+$B$16 -> 1 | F38: =+$B$18 -> 0 | G38: =+$B$20 -> 0 | K38: =25%*($B$17="ON") -> 0.25 | L38: =SUM(D38:K38) -> 16.015 | M38: =+B38*L38 -> 912855 | N38: =+N34-1 -> 6 | P38: =+$P$41 -> 0.17059891
A39: G6 Mounted | B39: 5700 | C39: 2 | D39: =+$B$15+10% -> 14.765 | F39: =+$B$18 -> 0 | H39: =+$B$21 -> 0 | K39: =25%*($B$17="ON") -> 0.25 | L39: =SUM(D39:K39) -> 15.015 | M39: =+B39*L39 -> 85585.5 | N39: =+N35-1 -> 6 | P39: =+$P$41 -> 0.17059891
A40: G6 Ranged | B40: 2820 | C40: 1 | D40: =+$B$15+10% -> 14.765 | F40: =+$B$18 -> 0 | I40: =+$B$22 -> 0 | K40: =25%*($B$17="ON") -> 0.25 | L40: =SUM(D40:K40) -> 15.015 | M40: =+B40*L40 -> 42342.3 | N40: =+N36-1 -> 6 | P40: =+$P$41 -> 0.17059891
A41: G6 Melee | B41: 2820 | C41: 1 | D41: =+$B$15+10% -> 14.765 | F41: =+$B$18 -> 0 | J41: =+$B$23 -> 0 | K41: =25%*($B$17="ON") -> 0.25 | L41: =SUM(D41:K41) -> 15.015 | M41: =+B41*L41 -> 42342.3 | N41: =+N37-1 -> 6 | P41: =+B41/$B$29 -> 0.17059891
...

Sheet Calcs
A1: INPUTS | C1: Aratilar | D1: Aradin | E1: Troidor | G1: Choose Opponent | H1: CP
B2: 3 | C2: 1 | D2: 2 | E2: 3
A3: Customization Bonus | B3: =+CHOOSE($B$2,C3,D3,E3) -> 0.175 | C3: 0.45 | E3: 0.175
A4: Talents (Troop Type) | B4: =+CHOOSE($B$2,C4,D4,E4) -> 2.5 | C4: 2.5 | E4: 2.5 | G4: Target Leadership: | H4: 227000
A5: Talents (G/S) | B5: =+CHOOSE($B$2,C5,D5,E5) -> 1.5 | C5: 1.5 | E5: 1.5 | G5: Calculated Leadership: | H5: =+C60 -> 223440 | I5: =+H4-H5 -> 3560
A6: Hall of Fame | B6: =+CHOOSE($B$2,C6,D6,E6) -> 1.2 | C6: 1.825 | E6: 1.2 | G6: Target Dominance: | H6: 161768
A7: Army Mod | B7: =+CHOOSE($B$2,C7,D7,E7) -> 3.1 | C7: 2.91 | E7: =31%+50%+60%+70%+80%+19% -> 3.1 | G7: Calculated Dominance: | H7: =+I60 -> 58200
A8: Health of Captain (Army) | B8: =+CHOOSE($B$2,C8,D8,E8) -> 0 | C8: 4.27 | E8: 0 | G8: Stacks | H8: =+MAX(A63:A85) -> 12
A9: Health of Artifact | B9: =+CHOOSE($B$2,C9,D9,E9) -> 0 | C9: =240%+87% -> 3.27 | E9: 0 | G9: Max Stack Level | H9: =+MAX(E63:E85) -> 9
A10: Health of Equipment | B10: =+CHOOSE($B$2,C10,D10,E10) -> 3 | C10: 2.8 | E10: 3 | G10: Stacks lvl 1 | H10: =+COUNTIF($E$63:$E$85,$H$9) -> 4 | I10: =+H10/1 -> 4
A11: Dragon | B11: =+CHOOSE($B$2,C11,D11,E11) -> 1.6 | C11: 1.6 | E11: 1.6 | G11: Stacks lvl 2 | H11: =+COUNTIF($E$63:$E$85,$H$9-1) -> 8 | I11: =+H11/J14 -> 14.405229
A12: VIP | B12: =+CHOOSE($B$2,C12,D12,E12) -> 0.09 | C12: 0.2 | E12: 0.09 | G12: Stacks lvl 3 | H12: =+COUNTIF($E$63:$E$85,$H$9-2) -> 0 | I12: =+H12/J15 -> 0
A13: Clan Capital | B13: =+CHOOSE($B$2,C13,D13,E13) -> 1 | C13: 1 | E13: 1 | G13: Stack lvl 1 % | H13: =+I10/SUM($I$10:$I$12) -> 0.21732955 | I13: =+IFERROR(H13/H10,"") -> 0.054332386 | J13: 1 | K13: =+SUMIF('Base Data'!$N$26:$N$57,$H$9,'Base Data'!$P$26:$P$57)/4 -> 1
A14: Clan Army Health Bonus | B14: =+CHOOSE($B$2,C14,D14,E14) -> 0.25 | C14: 0.25 | E14: 0.25 | G14: Stack lvl 2 % | H14: =+I11/SUM($I$10:$I$12) -> 0.78267045 | I14: =+IFERROR(H14/H11,"") -> 0.097833807 | J14: =+K14/$K$13 -> 0.5553539 | K14: =+SUMIF('Base Data'!$N$26:$N$57,$H$9-1,'Base Data'!$P$26:$P$57)/4 -> 0.5553539
A15: Personal Bonuses | B15: =+CHOOSE($B$2,C15,D15,E15) -> 0.25 | C15: 0.25 | E15: 0.25 | G15: Stack lvl 3 % | H15: =+I12/SUM($I$10:$I$12) -> 0 | I15: =+IFERROR(H15/H12,"") | J15: =+K15/$K$13 -> 0.30852995 | K15: =+SUMIF('Base Data'!$N$26:$N$57,$H$9-2,'Base Data'!$P$26:$P$57)/4 -> 0.30852995
A16: Total Bonus | B16: =+CHOOSE($B$2,C16,D16,E16) -> 14.665 | C16: =SUM(C3:C15) -> 22.825 | D16: =SUM(D3:D15) -> 0 | E16: =SUM(E3:E15) -> 14.665 | G16: Number of Stacks Active | H16: =+COUNTIF($H$10:$H$12,"<>0") -> 2 | I16: =+IF(E63=$H$9,1,IF(H9-E63=1,2,3)) -> 2
A17: Beasts Bonus (Talents) | B17: =+CHOOSE($B$2,C17,D17,E17) -> 1 | C17: 1 | E17: 1 | G17: Target Max Stack Health Troops | H17: =+H4*F63/G63*CHOOSE(H16,I13,I14,I15)*IF(E63=H9-H16+1,1,IF(E63=H9-H16+2,0.55,0.3025)) -> 3.0611374e+09
A18: Great Marshal | B18: =+CHOOSE($B$2,C18,D18,E18) -> ON | C18: ON | E18: ON
A19: Captain Bonus for Guardsmen | B19: =+CHOOSE($B$2,C19,D19,E19) -> 0 | C19: 0 | E19: 0 | G19: Error Check | H19: =+IF(SUM(K63:K85)>0,"Error","All OK") -> All OK
A20: Captain Bonus for Specialits | B20: =+CHOOSE($B$2,C20,D20,E20) -> 0 | C20: 0 | E20: 0 | P20: 384
A21: Captain Bonus for Flyings | B21: =+CHOOSE($B$2,C21,D21,E21) -> 0 | C21: =380%+280%+3*128% -> 10.44 | E21: 0 | G21: Rounding | H21: -1 | I21: Flyings Step | J21: =+IF(E21>0,$H$24,$H$23) -> 0.0001 | P21: 380
A22: Captain Bonus for Mounted | B22: =+CHOOSE($B$2,C22,D22,E22) -> 0 | C22: 0 | E22: 0 | G22: Monsters Step | H22: 0.0001 | I22: Mounted Step | J22: =+IF(E22>0,$H$24,$H$23) -> 0.0001 | P22: 280
A23: Captain Bonus for Ranged | B23: =+CHOOSE($B$2,C23,D23,E23) -> 0 | C23: 0 | E23: 0 | G23: Troops Step | H23: 0.0001 | I23: Ranged Step | J23: =+IF(E23>0,$H$24,$H$23) -> 0.0001 | P23: 261
A24: Captain Bonus for Melee | B24: =+CHOOSE($B$2,C24,D24,E24) -> 0 | C24: 0 | E24: 0 | G24: Adjusted Step | H24: 0.01 | I24: Melee Step | J24: =+IF(E24>0,$H$24,$H$23) -> 0.0001 | P24: =SUM(P20:P23) -> 1305
A26: Normal Troops | B26: Army | C26: Leadership | D26: Actual Rank | G26: Monsters | H26: Army | I26: Dominance | J26: Actual Rank
A27: G9 Flyings | B27: =+SUMIF($B$63:$B$85,A27,$C$63:$C$85) -> 600 | C27: =+SUMIF($B$63:$B$85,A27,$D$63:$D$85) -> 12000 | D27: =+SUMIF($B$63:$B$85,A27,$J$63:$J$85) -> 10 | E27: =+B27*10 -> 6000 | G27: M9 Ranged | H27: =+SUMIF($B$89:$B$111,G27,$C$89:$C$111) -> 40 | I27: =+SUMIF($B$89:$B$111,G27,$D$89:$D$111) -> 2080 | J27: =+SUMIF($B$89:$B$111,G27,$J$89:$J$111) -> 12
A28: S9 Flyings | B28: =+SUMIF($B$63:$B$85,A28,$C$63:$C$85) -> 0 | C28: =+SUMIF($B$63:$B$85,A28,$D$63:$D$85) -> 0 | D28: =+SUMIF($B$63:$B$85,A28,$J$63:$J$85) -> 0 | E28: =+B28*10 -> 0 | G28: M9 Melee | H28: =+SUMIF($B$89:$B$111,G28,$C$89:$C$111) -> 40 | I28: =+SUMIF($B$89:$B$111,G28,$D$89:$D$111) -> 2200 | J28: =+SUMIF($B$89:$B$111,G28,$J$89:$J$111) -> 9 | O28: =16/7.5 -> 2.1333333
A29: G8 Flyings | B29: =+SUMIF($B$63:$B$85,A29,$C$63:$C$85) -> 1100 | C29: =+SUMIF($B$63:$B$85,A29,$D$63:$D$85) -> 22000 | D29: =+SUMIF($B$63:$B$85,A29,$J$63:$J$85) -> 6 | E29: =+B29*10 -> 11000 | G29: M9 Mounted | H29: =+SUMIF($B$89:$B$111,G29,$C$89:$C$111) -> 40 | I29: =+SUMIF($B$89:$B$111,G29,$D$89:$D$111) -> 2120 | J29: =+SUMIF($B$89:$B$111,G29,$J$89:$J$111) -> 11
A30: S8 Flyings | B30: =+SUMIF($B$63:$B$85,A30,$C$63:$C$85) -> 1010 | C30: =+SUMIF($B$63:$B$85,A30,$D$63:$D$85) -> 20200 | D30: =+SUMIF($B$63:$B$85,A30,$J$63:$J$85) -> 12 | E30: =+B30*10 -> 10100 | G30: M9 Flyings | H30: =+SUMIF($B$89:$B$111,G30,$C$89:$C$111) -> 40 | I30: =+SUMIF($B$89:$B$111,G30,$D$89:$D$111) -> 2160 | J30: =+SUMIF($B$89:$B$111,G30,$J$89:$J$111) -> 10
A31: G7 Flyings | B31: =+SUMIF($B$63:$B$85,A31,$C$63:$C$85) -> 0 | C31: =+SUMIF($B$63:$B$85,A31,$D$63:$D$85) -> 0 | D31: =+SUMIF($B$63:$B$85,A31,$J$63:$J$85) -> 0 | E31: =+B31*10 -> 0 | G31: M8 Ranged | H31: =+SUMIF($B$89:$B$111,G31,$C$89:$C$111) -> 80 | I31: =+SUMIF($B$89:$B$111,G31,$D$89:$D$111) -> 4160 | J31: =+SUMIF($B$89:$B$111,G31,$J$89:$J$111) -> 8
A32: S7 Flyings | B32: =+SUMIF($B$63:$B$85,A32,$C$63:$C$85) -> 0 | C32: =+SUMIF($B$63:$B$85,A32,$D$63:$D$85) -> 0 | D32: =+SUMIF($B$63:$B$85,A32,$J$63:$J$85) -> 0 | E32: =+B32*10 -> 0 | G32: M8 Melee | H32: =+SUMIF($B$89:$B$111,G32,$C$89:$C$111) -> 80 | I32: =+SUMIF($B$89:$B$111,G32,$D$89:$D$111) -> 4400 | J32: =+SUMIF($B$89:$B$111,G32,$J$89:$J$111) -> 5
A33: G6 Flyings | B33: =+SUMIF($B$63:$B$85,A33,$C$63:$C$85) -> 0 | C33: =+SUMIF($B$63:$B$85,A33,$D$63:$D$85) -> 0 | D33: =+SUMIF($B$63:$B$85,A33,$J$63:$J$85) -> 0 | E33: =+B33*10 -> 0 | G33: M8 Mounted | H33: =+SUMIF($B$89:$B$111,G33,$C$89:$C$111) -> 80 | I33: =+SUMIF($B$89:$B$111,G33,$D$89:$D$111) -> 4240 | J33: =+SUMIF($B$89:$B$111,G33,$J$89:$J$111) -> 7
A34: G5 Flyings | B34: =+SUMIF($B$63:$B$85,A34,$C$63:$C$85) -> 0 | C34: =+SUMIF($B$63:$B$85,A34,$D$63:$D$85) -> 0 | D34: =+SUMIF($B$63:$B$85,A34,$J$63:$J$85) -> 0 | E34: =+B34*10 -> 0 | G34: M8 Flyings | H34: =+SUMIF($B$89:$B$111,G34,$C$89:$C$111) -> 80 | I34: =+SUMIF($B$89:$B$111,G34,$D$89:$D$111) -> 4320 | J34: =+SUMIF($B$89:$B$111,G34,$J$89:$J$111) -> 6
A35: G9 Mounted | B35: =+SUMIF($B$63:$B$85,A35,$C$63:$C$85) -> 6100 | C35: =+SUMIF($B$63:$B$85,A35,$D$63:$D$85) -> 12200 | D35: =+SUMIF($B$63:$B$85,A35,$J$63:$J$85) -> 9 | E35: =+B35*10 -> 61000 | G35: M7 Ranged | H35: =+SUMIF($B$89:$B$111,G35,$C$89:$C$111) -> 190 | I35: =+SUMIF($B$89:$B$111,G35,$D$89:$D$111) -> 8170 | J35: =+SUMIF($B$89:$B$111,G35,$J$89:$J$111) -> 4
A36: S9 Mounted | B36: =+SUMIF($B$63:$B$85,A36,$C$63:$C$85) -> 0 | C36: =+SUMIF($B$63:$B$85,A36,$D$63:$D$85) -> 0 | D36: =+SUMIF($B$63:$B$85,A36,$J$63:$J$85) -> 0 | E36: =+B36*10 -> 0 | G36: M7 Melee | H36: =+SUMIF($B$89:$B$111,G36,$C$89:$C$111) -> 190 | I36: =+SUMIF($B$89:$B$111,G36,$D$89:$D$111) -> 7790 | J36: =+SUMIF($B$89:$B$111,G36,$J$89:$J$111) -> 1
A37: G8 Mounted | B37: =+SUMIF($B$63:$B$85,A37,$C$63:$C$85) -> 11070 | C37: =+SUMIF($B$63:$B$85,A37,$D$63:$D$85) -> 22140 | D37: =+SUMIF($B$63:$B$85,A37,$J$63:$J$85) -> 5 | E37: =+B37*10 -> 110700 | G37: M7 Mounted | H37: =+SUMIF($B$89:$B$111,G37,$C$89:$C$111) -> 200 | I37: =+SUMIF($B$89:$B$111,G37,$D$89:$D$111) -> 8200 | J37: =+SUMIF($B$89:$B$111,G37,$J$89:$J$111) -> 3
A38: S8 Mounted | B38: =+SUMIF($B$63:$B$85,A38,$C$63:$C$85) -> 11090 | C38: =+SUMIF($B$63:$B$85,A38,$D$63:$D$85) -> 22180 | D38: =+SUMIF($B$63:$B$85,A38,$J$63:$J$85) -> 2 | E38: =+B38*10 -> 110900 | G38: M7 Flyings | H38: =+SUMIF($B$89:$B$111,G38,$C$89:$C$111) -> 190 | I38: =+SUMIF($B$89:$B$111,G38,$D$89:$D$111) -> 8360 | J38: =+SUMIF($B$89:$B$111,G38,$J$89:$J$111) -> 2
A39: G7 Mounted | B39: =+SUMIF($B$63:$B$85,A39,$C$63:$C$85) -> 0 | C39: =+SUMIF($B$63:$B$85,A39,$D$63:$D$85) -> 0 | D39: =+SUMIF($B$63:$B$85,A39,$J$63:$J$85) -> 0 | E39: =+B39*10 -> 0
A40: S7 Mounted | B40: =+SUMIF($B$63:$B$85,A40,$C$63:$C$85) -> 0 | C40: =+SUMIF($B$63:$B$85,A40,$D$63:$D$85) -> 0 | D40: =+SUMIF($B$63:$B$85,A40,$J$63:$J$85) -> 0 | E40: =+B40*10 -> 0
A41: G6 Mounted | B41: =+SUMIF($B$63:$B$85,A41,$C$63:$C$85) -> 0 | C41: =+SUMIF($B$63:$B$85,A41,$D$63:$D$85) -> 0 | D41: =+SUMIF($B$63:$B$85,A41,$J$63:$J$85) -> 0 | E41: =+B41*10 -> 0
...

Sheet RSS
A1: SILVER | E1: EPIC TAR | I1: RARE TAR | M1: DCs
A2: 5000 | B2: 558 | C2: =+A2*B2 -> 2790000 | E2: 5000 | F2: 0 | G2: =+E2*F2 -> 0 | I2: 7500 | J2: 3 | K2: =+I2*J2 -> 22500 | M2: 50000 | N2: 150 | O2: =+M2*N2 -> 7500000
A3: 3000 | B3: 30 | C3: =+A3*B3 -> 90000 | E3: 15000 | F3: 360 | G3: =+E3*F3 -> 5400000 | I3: 15000 | J3: 645 | K3: =+I3*J3 -> 9675000 | M3: 100000 | N3: 130 | O3: =+M3*N3 -> 13000000
A4: 1500 | B4: 36 | C4: =+A4*B4 -> 54000 | E4: TOTAL | G4: =SUM(G2:G3) -> 5400000 | I4: TOTAL | K4: =SUM(K2:K3) -> 9697500 | M4: TOTAL | O4: =SUM(O2:O3) -> 20500000
A5: 1200 | B5: 0 | C5: =+A5*B5 -> 0
A6: 1000 | B6: 0 | C6: =+A6*B6 -> 0
A7: 750 | B7: 34 | C7: =+A7*B7 -> 25500
A8: 500 | B8: 0 | C8: =+A8*B8 -> 0
A9: 250 | B9: 0 | C9: =+A9*B9 -> 0
A10: 45 | B10: 0 | C10: =+A10*B10 -> 0
A11: 15 | B11: 0 | C11: =+A11*B11 -> 0
A12: TOTAL | C12: =SUM(C2:C11) -> 2959500
B15: 700000 | C15: =+B15*100 -> 70000000
G16: 35
G17: 35
G18: 17
G19: =SUM(G16:G18) -> 87
G20: 17 | H20: =1000/G20 -> 58.823529 | I20: =+H20*700000 -> 41176471
I21: =+I20*12 -> 4.9411765e+08
